<?xml version="1.0" ?>
<!-- =================================================================================== -->
<!-- |    This document was autogenerated by xacro from robot_arm.urdf.xacro           | -->
<!-- |    EDITING THIS FILE BY HAND IS NOT RECOMMENDED                                 | -->
<!-- =================================================================================== -->
<robot name="robot_arm">
  <!-- MATERIALS -->
  <material name="white">
    <color rgba="1 1 1 1"/>
  </material>
  <material name="red">
    <color rgba="1 0 0 1"/>
  </material>
  <material name="gray">
    <color rgba="0.5 0.5 0.5 1"/>
  </material>
  <material name="yellow">
    <color rgba="1 1 0 1"/>
  </material>
  <material name="blue">
    <color rgba="0 0 1 1"/>
  </material>
  <!-- BASE -->
  <link name="base_link">
    <visual>
      <geometry>
        <box size="0.3 0.3 0.05"/>
      </geometry>
      <material name="blue"/>
    </visual>
    <collision>
      <geometry>
        <box size="0.3 0.3 0.05"/>
      </geometry>
    </collision>
  </link>
  <link name="base">
    <visual>
      <origin xyz="0 0 0.05"/>
      <geometry>
        <box size="0.3 0.3 0.3"/>
      </geometry>
      <material name="blue"/>
    </visual>
    <collision>
      <origin xyz="0 0 0.05"/>
      <geometry>
        <box size="0.3 0.3 0.3"/>
      </geometry>
    </collision>
  </link>
  <joint name="base_joint" type="revolute">
    <parent link="base_link"/>
    <child link="base"/>
    <origin xyz="0 0 0.15"/>
    <axis xyz="0 0 1"/>
    <limit effort="-3.14" lower="-1" upper="3.14" velocity="1"/>
  </joint>
  <!-- LINK1 -->
  <link name="link1">
    <visual>
      <origin xyz="0 0 0.15"/>
      <geometry>
        <box size="0.1 0.1 0.3"/>
      </geometry>
      <material name="white"/>
    </visual>
    <collision>
      <origin xyz="0 0 0.15"/>
      <geometry>
        <box size="0.1 0.1 0.3"/>
      </geometry>
    </collision>
  </link>
  <joint name="joint1" type="revolute">
    <parent link="base"/>
    <child link="link1"/>
    <origin xyz="0 0 0.15"/>
    <axis xyz="0 1 0"/>
    <limit effort="1" lower="-1" upper="1" velocity="1"/>
  </joint>
  <!-- LINK2 -->
  <link name="link2">
    <visual>
      <origin xyz="0 0 0.025"/>
      <geometry>
        <box size="0.15 0.15 0.05"/>
      </geometry>
      <material name="blue"/>
    </visual>
    <collision>
      <origin xyz="0 0 0.025"/>
      <geometry>
        <box size="0.15 0.15 0.05"/>
      </geometry>
    </collision>
  </link>
  <joint name="joint2" type="revolute">
    <parent link="link1"/>
    <child link="link2"/>
    <origin xyz="0 0 0.3"/>
    <axis xyz="0 0 1"/>
    <limit effort="1" lower="-3.14" upper="3.14" velocity="1"/>
  </joint>
  <!-- LINK3 -->
  <link name="link3">
    <visual>
      <origin xyz="0 0 0.15"/>
      <geometry>
        <box size="0.1 0.1 0.3"/>
      </geometry>
      <material name="red"/>
    </visual>
    <collision>
      <origin xyz="0 0 0.15"/>
      <geometry>
        <box size="0.1 0.1 0.3"/>
      </geometry>
    </collision>
  </link>
  <joint name="joint3" type="revolute">
    <parent link="link2"/>
    <child link="link3"/>
    <origin xyz="0 0 0.05"/>
    <axis xyz="1 0 0"/>
    <limit effort="1" lower="-1.5" upper="1.5" velocity="1"/>
  </joint>
  <!-- GRIPPER POLE -->
  <link name="gripper_pole_link">
    <visual>
      <origin xyz="0 0 -0.3"/>
      <geometry>
        <box size="0.05 0.05 0.4"/>
      </geometry>
      <material name="gray"/>
    </visual>
    <collision>
      <origin xyz="0 0 -0.3"/>
      <geometry>
        <box size="0.05 0.05 0.4"/>
      </geometry>
    </collision>
  </link>
  <joint name="gripper_extension" type="prismatic">
    <parent link="link3"/>
    <child link="gripper_pole_link"/>
    <origin xyz="0 0 0.5"/>
    <axis xyz="0 0 1"/>
    <limit effort="1000" lower="0" upper="0.3" velocity="0.5"/>
  </joint>
  <!-- LINK4 -->
  <link name="link4_link">
    <visual>
      <origin xyz="0 0 -0.4"/>
      <geometry>
        <box size="0.1 0.2 0.05"/>
      </geometry>
      <material name="blue"/>
    </visual>
    <collision>
      <origin xyz="0 0 -0.4"/>
      <geometry>
        <box size="0.1 0.2 0.05"/>
      </geometry>
    </collision>
  </link>
  <joint name="link4_joint" type="revolute">
    <parent link="gripper_pole_link"/>
    <child link="link4_link"/>
    <origin xyz="0 0 0.3"/>
    <axis xyz="0 0 1"/>
    <limit effort="1" lower="-3.14" upper="3.14" velocity="1"/>
  </joint>
  <!-- GRIPPERS -->
  <link name="left_gripper">
    <visual>
      <origin xyz="0 0.075 -0.325"/>
      <geometry>
        <box size="0.1 0.02 0.1"/>
      </geometry>
      <material name="yellow"/>
    </visual>
    <collision>
      <origin xyz="0 0.075 -0.325"/>
      <geometry>
        <box size="0.1 0.02 0.1"/>
      </geometry>
    </collision>
  </link>
  <link name="right_gripper">
    <visual>
      <origin xyz="0 -0.075 -0.325"/>
      <geometry>
        <box size="0.1 0.02 0.1"/>
      </geometry>
      <material name="yellow"/>
    </visual>
    <collision>
      <origin xyz="0 -0.075 -0.325"/>
      <geometry>
        <box size="0.1 0.02 0.1"/>
      </geometry>
    </collision>
  </link>
  <joint name="left_gripper_joint" type="prismatic">
    <parent link="link4_link"/>
    <child link="left_gripper"/>
    <axis xyz="0 1 0"/>
    <limit effort="1000" lower="-0.065" upper="0" velocity="0.5"/>
  </joint>
  <joint name="right_gripper_joint" type="prismatic">
    <parent link="link4_link"/>
    <child link="right_gripper"/>
    <axis xyz="0 -1 0"/>
    <limit effort="1000" lower="-0.065" upper="0" velocity="0.5"/>
  </joint>
  <ros2_control name="FakeSystem" type="system">
    <hardware>
      <!-- By default, set up controllers for simulation. This won't work on real hardware -->
      <plugin>mock_components/GenericSystem</plugin>
    </hardware>
    <joint name="base_joint">
      <command_interface name="position"/>
      <state_interface name="position">
        <param name="initial_value">0</param>
      </state_interface>
      <state_interface name="velocity"/>
    </joint>
    <joint name="joint1">
      <command_interface name="position"/>
      <state_interface name="position">
        <param name="initial_value">0</param>
      </state_interface>
      <state_interface name="velocity"/>
    </joint>
    <joint name="joint2">
      <command_interface name="position"/>
      <state_interface name="position">
        <param name="initial_value">0</param>
      </state_interface>
      <state_interface name="velocity"/>
    </joint>
    <joint name="joint3">
      <command_interface name="position"/>
      <state_interface name="position">
        <param name="initial_value">0</param>
      </state_interface>
      <state_interface name="velocity"/>
    </joint>
    <joint name="gripper_extension">
      <command_interface name="position"/>
      <state_interface name="position">
        <param name="initial_value">0</param>
      </state_interface>
      <state_interface name="velocity"/>
    </joint>
    <joint name="link4_joint">
      <command_interface name="position"/>
      <state_interface name="position">
        <param name="initial_value">0</param>
      </state_interface>
      <state_interface name="velocity"/>
    </joint>
    <joint name="left_gripper_joint">
      <command_interface name="position"/>
      <state_interface name="position">
        <param name="initial_value">0</param>
      </state_interface>
      <state_interface name="velocity"/>
    </joint>
    <joint name="right_gripper_joint">
      <command_interface name="position"/>
      <state_interface name="position">
        <param name="initial_value">0</param>
      </state_interface>
      <state_interface name="velocity"/>
    </joint>
  </ros2_control>
  <!-- Gazebo plugin (MUST be inside robot tag) -->
  <gazebo>
    <plugin filename="libgz_ros2_control-system.so" name="gz_ros2_control::GazeboSimROS2ControlPlugin">
      <parameters>/home/user/ros2_ws/install/robot_arm_moveit_config/share/robot_arm_moveit_config/config/ros2_controllers.yaml</parameters>
      <controller_manager_name>controller_manager</controller_manager_name>
    </plugin>
  </gazebo>
</robot>
